Operations to perform:
  Apply all migrations: accounts, admin, auth, contenttypes, projects, sessions
Running migrations:
  Applying projects.0003_alter_message_options_and_more...Traceback (most recent call last):
  File "/home/runner/workspace/.pythonlibs/lib/python3.11/site-packages/django/db/models/fields/__init__.py", line 2128, in get_prep_value
    return int(value)
           ^^^^^^^^^^
TypeError: int() argument must be a string, a bytes-like object or a real number, not 'datetime.datetime'

The above exception was the direct cause of the following exception:

Traceback (most recent call last):
  File "/home/runner/workspace/crewd/manage.py", line 20, in <module>
    main()
  File "/home/runner/workspace/crewd/manage.py", line 16, in main
    execute_from_command_line(sys.argv)
  File "/home/runner/workspace/.pythonlibs/lib/python3.11/site-packages/django/core/management/__init__.py", line 442, in execute_from_command_line
    utility.execute()
  File "/home/runner/workspace/.pythonlibs/lib/python3.11/site-packages/django/core/management/__init__.py", line 436, in execute
    self.fetch_command(subcommand).run_from_argv(self.argv)
  File "/home/runner/workspace/.pythonlibs/lib/python3.11/site-packages/django/core/management/base.py", line 416, in run_from_argv
    self.execute(*args, **cmd_options)
  File "/home/runner/workspace/.pythonlibs/lib/python3.11/site-packages/django/core/management/base.py", line 460, in execute
    output = self.handle(*args, **options)
             ^^^^^^^^^^^^^^^^^^^^^^^^^^^^^
  File "/home/runner/workspace/.pythonlibs/lib/python3.11/site-packages/django/core/management/base.py", line 107, in wrapper
    res = handle_func(*args, **kwargs)
          ^^^^^^^^^^^^^^^^^^^^^^^^^^^^
  File "/home/runner/workspace/.pythonlibs/lib/python3.11/site-packages/django/core/management/commands/migrate.py", line 353, in handle
    post_migrate_state = executor.migrate(
                         ^^^^^^^^^^^^^^^^^
  File "/home/runner/workspace/.pythonlibs/lib/python3.11/site-packages/django/db/migrations/executor.py", line 135, in migrate
    state = self._migrate_all_forwards(
            ^^^^^^^^^^^^^^^^^^^^^^^^^^^
  File "/home/runner/workspace/.pythonlibs/lib/python3.11/site-packages/django/db/migrations/executor.py", line 167, in _migrate_all_forwards
    state = self.apply_migration(
            ^^^^^^^^^^^^^^^^^^^^^
  File "/home/runner/workspace/.pythonlibs/lib/python3.11/site-packages/django/db/migrations/executor.py", line 255, in apply_migration
    state = migration.apply(state, schema_editor)
            ^^^^^^^^^^^^^^^^^^^^^^^^^^^^^^^^^^^^^
  File "/home/runner/workspace/.pythonlibs/lib/python3.11/site-packages/django/db/migrations/migration.py", line 132, in apply
    operation.database_forwards(
  File "/home/runner/workspace/.pythonlibs/lib/python3.11/site-packages/django/db/migrations/operations/fields.py", line 241, in database_forwards
    schema_editor.alter_field(from_model, from_field, to_field)
  File "/home/runner/workspace/.pythonlibs/lib/python3.11/site-packages/django/db/backends/base/schema.py", line 912, in alter_field
    self._alter_field(
  File "/home/runner/workspace/.pythonlibs/lib/python3.11/site-packages/django/db/backends/sqlite3/schema.py", line 388, in _alter_field
    self._remake_table(model, alter_fields=[(old_field, new_field)])
  File "/home/runner/workspace/.pythonlibs/lib/python3.11/site-packages/django/db/backends/sqlite3/schema.py", line 165, in _remake_table
    default = self.prepare_default(self.effective_default(new_field))
                                   ^^^^^^^^^^^^^^^^^^^^^^^^^^^^^^^^^
  File "/home/runner/workspace/.pythonlibs/lib/python3.11/site-packages/django/db/backends/base/schema.py", line 490, in effective_default
    return field.get_db_prep_save(self._effective_default(field), self.connection)
           ^^^^^^^^^^^^^^^^^^^^^^^^^^^^^^^^^^^^^^^^^^^^^^^^^^^^^^^^^^^^^^^^^^^^^^^
  File "/home/runner/workspace/.pythonlibs/lib/python3.11/site-packages/django/db/models/fields/related.py", line 1189, in get_db_prep_save
    return self.target_field.get_db_prep_save(value, connection=connection)
           ^^^^^^^^^^^^^^^^^^^^^^^^^^^^^^^^^^^^^^^^^^^^^^^^^^^^^^^^^^^^^^^^
  File "/home/runner/workspace/.pythonlibs/lib/python3.11/site-packages/django/db/models/fields/__init__.py", line 1012, in get_db_prep_save
    return self.get_db_prep_value(value, connection=connection, prepared=False)
           ^^^^^^^^^^^^^^^^^^^^^^^^^^^^^^^^^^^^^^^^^^^^^^^^^^^^^^^^^^^^^^^^^^^^
  File "/home/runner/workspace/.pythonlibs/lib/python3.11/site-packages/django/db/models/fields/__init__.py", line 2820, in get_db_prep_value
    value = self.get_prep_value(value)
            ^^^^^^^^^^^^^^^^^^^^^^^^^^
  File "/home/runner/workspace/.pythonlibs/lib/python3.11/site-packages/django/db/models/fields/__init__.py", line 2130, in get_prep_value
    raise e.__class__(
TypeError: Field 'id' expected a number but got datetime.datetime(2025, 4, 8, 12, 55, 30, 401616, tzinfo=datetime.timezone.utc).